{"timestamp": "2025-08-01T10:49:12.363332", "level": "ERROR", "component": "trading.errors", "thread_id": 137681319940224, "process_id": 3654, "message": "Value error test", "exception": {"type": "ValueError", "message": "invalid literal for int() with base 10: 'not_a_number'", "traceback": "Traceback (most recent call last):\n  File \"/mnt/c/Users/ingle/OneDrive/Desktop/xgb_model/test_logging.py\", line 171, in test_error_handling\n    int('not_a_number')\nValueError: invalid literal for int() with base 10: 'not_a_number'"}, "extra": {"taskName": null, "input_value": "not_a_number"}}
{"timestamp": "2025-08-01T10:49:12.373878", "level": "ERROR", "component": "trading.errors", "thread_id": 137681319940224, "process_id": 3654, "message": "Key error test", "exception": {"type": "KeyError", "message": "'nonexistent_key'", "traceback": "Traceback (most recent call last):\n  File \"/mnt/c/Users/ingle/OneDrive/Desktop/xgb_model/test_logging.py\", line 182, in test_error_handling\n    _ = test_dict['nonexistent_key']\n        ~~~~~~~~~^^^^^^^^^^^^^^^^^^^\nKeyError: 'nonexistent_key'"}, "extra": {"taskName": null, "available_keys": ["key1"]}}
{"timestamp": "2025-08-01T10:49:12.383376", "level": "ERROR", "component": "trading.errors", "thread_id": 137681319940224, "process_id": 3654, "message": "Custom exception test", "exception": {"type": "RuntimeError", "message": "Custom test error for logging validation", "traceback": "Traceback (most recent call last):\n  File \"/mnt/c/Users/ingle/OneDrive/Desktop/xgb_model/test_logging.py\", line 192, in test_error_handling\n    raise RuntimeError(\"Custom test error for logging validation\")\nRuntimeError: Custom test error for logging validation"}, "extra": {"taskName": null, "custom_data": "test_context"}}
